2022-05-23 18:02:30,924 ERROR - LogGenerationFile: exception_logger_decorator - Line Number: 18 - Log:
Traceback (most recent call last):
  File "/home/warmongr/projects/octopus/backend/Octopus/diagnosis/testing_module/shared/exception_logger_decorator.py", line 15, in wrapper
    res = func(*args, **kwargs)
  File "/home/warmongr/projects/octopus/backend/Octopus/diagnosis/testing_module/can_module/get_can_conn.py", line 29, in get_can_connection
    raise e
  File "/home/warmongr/projects/octopus/backend/Octopus/diagnosis/testing_module/can_module/get_can_conn.py", line 25, in get_can_connection
    can_bus = connect_to_can()
  File "/home/warmongr/projects/octopus/backend/Octopus/diagnosis/testing_module/can_module/can_conn_create.py", line 21, in connect_to_can
    raise e
  File "/home/warmongr/projects/octopus/backend/Octopus/diagnosis/testing_module/can_module/can_conn_create.py", line 19, in connect_to_can
    power_up_can()
  File "/home/warmongr/projects/octopus/backend/Octopus/diagnosis/testing_module/can_module/can_powerup.py", line 29, in power_up_can
    raise CANPowerUpError
testing_module.can_module.can_exceptions.CANPowerUpError
2022-05-24 18:35:26,363 ERROR - LogGenerationFile: exception_logger_decorator - Line Number: 18 - Log:
Traceback (most recent call last):
  File "/home/warmongr/projects/octopus/backend/Octopus/diagnosis/testing_module/shared/exception_logger_decorator.py", line 15, in wrapper
    res = func(*args, **kwargs)
  File "/home/warmongr/projects/octopus/backend/Octopus/diagnosis/testing_module/can_module/get_can_conn.py", line 29, in get_can_connection
    raise e
  File "/home/warmongr/projects/octopus/backend/Octopus/diagnosis/testing_module/can_module/get_can_conn.py", line 25, in get_can_connection
    can_bus = connect_to_can()
  File "/home/warmongr/projects/octopus/backend/Octopus/diagnosis/testing_module/can_module/can_conn_create.py", line 21, in connect_to_can
    raise e
  File "/home/warmongr/projects/octopus/backend/Octopus/diagnosis/testing_module/can_module/can_conn_create.py", line 19, in connect_to_can
    power_up_can()
  File "/home/warmongr/projects/octopus/backend/Octopus/diagnosis/testing_module/can_module/can_powerup.py", line 29, in power_up_can
    raise CANPowerUpError
testing_module.can_module.can_exceptions.CANPowerUpError
2022-05-24 18:45:21,126 ERROR - LogGenerationFile: exception_logger_decorator - Line Number: 18 - Log:
Traceback (most recent call last):
  File "/home/warmongr/projects/octopus/backend/Octopus/diagnosis/testing_module/shared/exception_logger_decorator.py", line 15, in wrapper
    res = func(*args, **kwargs)
  File "/home/warmongr/projects/octopus/backend/Octopus/diagnosis/testing_module/can_module/get_can_conn.py", line 29, in get_can_connection
    raise e
  File "/home/warmongr/projects/octopus/backend/Octopus/diagnosis/testing_module/can_module/get_can_conn.py", line 25, in get_can_connection
    can_bus = connect_to_can()
  File "/home/warmongr/projects/octopus/backend/Octopus/diagnosis/testing_module/can_module/can_conn_create.py", line 21, in connect_to_can
    raise e
  File "/home/warmongr/projects/octopus/backend/Octopus/diagnosis/testing_module/can_module/can_conn_create.py", line 19, in connect_to_can
    power_up_can()
  File "/home/warmongr/projects/octopus/backend/Octopus/diagnosis/testing_module/can_module/can_powerup.py", line 29, in power_up_can
    raise CANPowerUpError
testing_module.can_module.can_exceptions.CANPowerUpError
2022-05-30 15:32:59,374 ERROR - LogGenerationFile: exception_logger_decorator - Line Number: 18 - Log:
Traceback (most recent call last):
  File "/home/warmongr/projects/bms_charts/testing_module/shared/exception_logger_decorator.py", line 15, in wrapper
    res = func(*args, **kwargs)
  File "/home/warmongr/projects/bms_charts/testing_module/can_module/get_can_conn.py", line 29, in get_can_connection
    raise e
  File "/home/warmongr/projects/bms_charts/testing_module/can_module/get_can_conn.py", line 25, in get_can_connection
    can_bus = connect_to_can()
  File "/home/warmongr/projects/bms_charts/testing_module/can_module/can_conn_create.py", line 21, in connect_to_can
    raise e
  File "/home/warmongr/projects/bms_charts/testing_module/can_module/can_conn_create.py", line 19, in connect_to_can
    power_up_can()
  File "/home/warmongr/projects/bms_charts/testing_module/can_module/can_powerup.py", line 29, in power_up_can
    raise CANPowerUpError
testing_module.can_module.can_exceptions.CANPowerUpError
2022-05-30 15:50:45,617 ERROR - LogGenerationFile: exception_logger_decorator - Line Number: 18 - Log:
Traceback (most recent call last):
  File "/home/warmongr/projects/bms_charts/testing_module/shared/exception_logger_decorator.py", line 15, in wrapper
    res = func(*args, **kwargs)
  File "/home/warmongr/projects/bms_charts/testing_module/can_module/get_can_conn.py", line 29, in get_can_connection
    raise e
  File "/home/warmongr/projects/bms_charts/testing_module/can_module/get_can_conn.py", line 25, in get_can_connection
    can_bus = connect_to_can()
  File "/home/warmongr/projects/bms_charts/testing_module/can_module/can_conn_create.py", line 21, in connect_to_can
    raise e
  File "/home/warmongr/projects/bms_charts/testing_module/can_module/can_conn_create.py", line 19, in connect_to_can
    power_up_can()
  File "/home/warmongr/projects/bms_charts/testing_module/can_module/can_powerup.py", line 29, in power_up_can
    raise CANPowerUpError
testing_module.can_module.can_exceptions.CANPowerUpError
2022-05-30 15:54:10,284 ERROR - LogGenerationFile: exception_logger_decorator - Line Number: 18 - Log:
Traceback (most recent call last):
  File "/home/warmongr/projects/bms_charts/testing_module/shared/exception_logger_decorator.py", line 15, in wrapper
    res = func(*args, **kwargs)
  File "/home/warmongr/projects/bms_charts/testing_module/can_module/get_can_conn.py", line 29, in get_can_connection
    raise e
  File "/home/warmongr/projects/bms_charts/testing_module/can_module/get_can_conn.py", line 25, in get_can_connection
    can_bus = connect_to_can()
  File "/home/warmongr/projects/bms_charts/testing_module/can_module/can_conn_create.py", line 21, in connect_to_can
    raise e
  File "/home/warmongr/projects/bms_charts/testing_module/can_module/can_conn_create.py", line 19, in connect_to_can
    power_up_can()
  File "/home/warmongr/projects/bms_charts/testing_module/can_module/can_powerup.py", line 29, in power_up_can
    raise CANPowerUpError
testing_module.can_module.can_exceptions.CANPowerUpError
2022-05-30 16:15:12,762 ERROR - LogGenerationFile: exception_logger_decorator - Line Number: 18 - Log:
Traceback (most recent call last):
  File "/home/warmongr/projects/bms_charts/testing_module/shared/exception_logger_decorator.py", line 15, in wrapper
    res = func(*args, **kwargs)
  File "/home/warmongr/projects/bms_charts/testing_module/can_module/get_can_conn.py", line 29, in get_can_connection
    raise e
  File "/home/warmongr/projects/bms_charts/testing_module/can_module/get_can_conn.py", line 25, in get_can_connection
    can_bus = connect_to_can()
  File "/home/warmongr/projects/bms_charts/testing_module/can_module/can_conn_create.py", line 21, in connect_to_can
    raise e
  File "/home/warmongr/projects/bms_charts/testing_module/can_module/can_conn_create.py", line 19, in connect_to_can
    power_up_can()
  File "/home/warmongr/projects/bms_charts/testing_module/can_module/can_powerup.py", line 29, in power_up_can
    raise CANPowerUpError
testing_module.can_module.can_exceptions.CANPowerUpError
2022-05-30 17:36:33,494 ERROR - LogGenerationFile: exception_logger_decorator - Line Number: 18 - Log:
Traceback (most recent call last):
  File "/home/warmongr/projects/bms_charts/testing_module/shared/exception_logger_decorator.py", line 15, in wrapper
    res = func(*args, **kwargs)
  File "/home/warmongr/projects/bms_charts/testing_module/can_module/get_can_conn.py", line 29, in get_can_connection
    raise e
  File "/home/warmongr/projects/bms_charts/testing_module/can_module/get_can_conn.py", line 25, in get_can_connection
    can_bus = connect_to_can()
  File "/home/warmongr/projects/bms_charts/testing_module/can_module/can_conn_create.py", line 21, in connect_to_can
    raise e
  File "/home/warmongr/projects/bms_charts/testing_module/can_module/can_conn_create.py", line 19, in connect_to_can
    power_up_can()
  File "/home/warmongr/projects/bms_charts/testing_module/can_module/can_powerup.py", line 29, in power_up_can
    raise CANPowerUpError
testing_module.can_module.can_exceptions.CANPowerUpError
2022-05-30 17:37:25,851 ERROR - LogGenerationFile: exception_logger_decorator - Line Number: 18 - Log:
Traceback (most recent call last):
  File "/home/warmongr/projects/bms_charts/testing_module/shared/exception_logger_decorator.py", line 15, in wrapper
    res = func(*args, **kwargs)
  File "/home/warmongr/projects/bms_charts/testing_module/can_module/get_can_conn.py", line 29, in get_can_connection
    raise e
  File "/home/warmongr/projects/bms_charts/testing_module/can_module/get_can_conn.py", line 25, in get_can_connection
    can_bus = connect_to_can()
  File "/home/warmongr/projects/bms_charts/testing_module/can_module/can_conn_create.py", line 21, in connect_to_can
    raise e
  File "/home/warmongr/projects/bms_charts/testing_module/can_module/can_conn_create.py", line 19, in connect_to_can
    power_up_can()
  File "/home/warmongr/projects/bms_charts/testing_module/can_module/can_powerup.py", line 29, in power_up_can
    raise CANPowerUpError
testing_module.can_module.can_exceptions.CANPowerUpError
2022-05-30 17:37:49,527 ERROR - LogGenerationFile: exception_logger_decorator - Line Number: 18 - Log:
Traceback (most recent call last):
  File "/home/warmongr/projects/bms_charts/testing_module/shared/exception_logger_decorator.py", line 15, in wrapper
    res = func(*args, **kwargs)
  File "/home/warmongr/projects/bms_charts/testing_module/can_module/get_can_conn.py", line 29, in get_can_connection
    raise e
  File "/home/warmongr/projects/bms_charts/testing_module/can_module/get_can_conn.py", line 25, in get_can_connection
    can_bus = connect_to_can()
  File "/home/warmongr/projects/bms_charts/testing_module/can_module/can_conn_create.py", line 21, in connect_to_can
    raise e
  File "/home/warmongr/projects/bms_charts/testing_module/can_module/can_conn_create.py", line 19, in connect_to_can
    power_up_can()
  File "/home/warmongr/projects/bms_charts/testing_module/can_module/can_powerup.py", line 29, in power_up_can
    raise CANPowerUpError
testing_module.can_module.can_exceptions.CANPowerUpError
2022-05-30 17:38:09,546 ERROR - LogGenerationFile: exception_logger_decorator - Line Number: 18 - Log:
Traceback (most recent call last):
  File "/home/warmongr/projects/bms_charts/testing_module/shared/exception_logger_decorator.py", line 15, in wrapper
    res = func(*args, **kwargs)
  File "/home/warmongr/projects/bms_charts/testing_module/can_module/get_can_conn.py", line 29, in get_can_connection
    raise e
  File "/home/warmongr/projects/bms_charts/testing_module/can_module/get_can_conn.py", line 25, in get_can_connection
    can_bus = connect_to_can()
  File "/home/warmongr/projects/bms_charts/testing_module/can_module/can_conn_create.py", line 21, in connect_to_can
    raise e
  File "/home/warmongr/projects/bms_charts/testing_module/can_module/can_conn_create.py", line 19, in connect_to_can
    power_up_can()
  File "/home/warmongr/projects/bms_charts/testing_module/can_module/can_powerup.py", line 29, in power_up_can
    raise CANPowerUpError
testing_module.can_module.can_exceptions.CANPowerUpError
2022-05-30 17:38:35,197 ERROR - LogGenerationFile: exception_logger_decorator - Line Number: 18 - Log:
Traceback (most recent call last):
  File "/home/warmongr/projects/bms_charts/testing_module/shared/exception_logger_decorator.py", line 15, in wrapper
    res = func(*args, **kwargs)
  File "/home/warmongr/projects/bms_charts/testing_module/can_module/get_can_conn.py", line 29, in get_can_connection
    raise e
  File "/home/warmongr/projects/bms_charts/testing_module/can_module/get_can_conn.py", line 25, in get_can_connection
    can_bus = connect_to_can()
  File "/home/warmongr/projects/bms_charts/testing_module/can_module/can_conn_create.py", line 21, in connect_to_can
    raise e
  File "/home/warmongr/projects/bms_charts/testing_module/can_module/can_conn_create.py", line 19, in connect_to_can
    power_up_can()
  File "/home/warmongr/projects/bms_charts/testing_module/can_module/can_powerup.py", line 29, in power_up_can
    raise CANPowerUpError
testing_module.can_module.can_exceptions.CANPowerUpError
2022-05-30 17:39:38,181 ERROR - LogGenerationFile: exception_logger_decorator - Line Number: 18 - Log:
Traceback (most recent call last):
  File "/home/warmongr/projects/bms_charts/testing_module/shared/exception_logger_decorator.py", line 15, in wrapper
    res = func(*args, **kwargs)
  File "/home/warmongr/projects/bms_charts/testing_module/can_module/get_can_conn.py", line 29, in get_can_connection
    raise e
  File "/home/warmongr/projects/bms_charts/testing_module/can_module/get_can_conn.py", line 25, in get_can_connection
    can_bus = connect_to_can()
  File "/home/warmongr/projects/bms_charts/testing_module/can_module/can_conn_create.py", line 21, in connect_to_can
    raise e
  File "/home/warmongr/projects/bms_charts/testing_module/can_module/can_conn_create.py", line 19, in connect_to_can
    power_up_can()
  File "/home/warmongr/projects/bms_charts/testing_module/can_module/can_powerup.py", line 29, in power_up_can
    raise CANPowerUpError
testing_module.can_module.can_exceptions.CANPowerUpError
2022-05-30 17:40:06,760 ERROR - LogGenerationFile: exception_logger_decorator - Line Number: 18 - Log:
Traceback (most recent call last):
  File "/home/warmongr/projects/bms_charts/testing_module/shared/exception_logger_decorator.py", line 15, in wrapper
    res = func(*args, **kwargs)
  File "/home/warmongr/projects/bms_charts/testing_module/can_module/get_can_conn.py", line 29, in get_can_connection
    raise e
  File "/home/warmongr/projects/bms_charts/testing_module/can_module/get_can_conn.py", line 25, in get_can_connection
    can_bus = connect_to_can()
  File "/home/warmongr/projects/bms_charts/testing_module/can_module/can_conn_create.py", line 21, in connect_to_can
    raise e
  File "/home/warmongr/projects/bms_charts/testing_module/can_module/can_conn_create.py", line 19, in connect_to_can
    power_up_can()
  File "/home/warmongr/projects/bms_charts/testing_module/can_module/can_powerup.py", line 29, in power_up_can
    raise CANPowerUpError
testing_module.can_module.can_exceptions.CANPowerUpError
2022-05-30 17:44:43,814 ERROR - LogGenerationFile: exception_logger_decorator - Line Number: 18 - Log:
Traceback (most recent call last):
  File "/home/warmongr/projects/bms_charts/testing_module/shared/exception_logger_decorator.py", line 15, in wrapper
    res = func(*args, **kwargs)
  File "/home/warmongr/projects/bms_charts/testing_module/can_module/get_can_conn.py", line 29, in get_can_connection
    raise e
  File "/home/warmongr/projects/bms_charts/testing_module/can_module/get_can_conn.py", line 25, in get_can_connection
    can_bus = connect_to_can()
  File "/home/warmongr/projects/bms_charts/testing_module/can_module/can_conn_create.py", line 21, in connect_to_can
    raise e
  File "/home/warmongr/projects/bms_charts/testing_module/can_module/can_conn_create.py", line 19, in connect_to_can
    power_up_can()
  File "/home/warmongr/projects/bms_charts/testing_module/can_module/can_powerup.py", line 29, in power_up_can
    raise CANPowerUpError
testing_module.can_module.can_exceptions.CANPowerUpError
2022-05-30 17:44:58,077 ERROR - LogGenerationFile: exception_logger_decorator - Line Number: 18 - Log:
Traceback (most recent call last):
  File "/home/warmongr/projects/bms_charts/testing_module/shared/exception_logger_decorator.py", line 15, in wrapper
    res = func(*args, **kwargs)
  File "/home/warmongr/projects/bms_charts/testing_module/can_module/get_can_conn.py", line 29, in get_can_connection
    raise e
  File "/home/warmongr/projects/bms_charts/testing_module/can_module/get_can_conn.py", line 25, in get_can_connection
    can_bus = connect_to_can()
  File "/home/warmongr/projects/bms_charts/testing_module/can_module/can_conn_create.py", line 21, in connect_to_can
    raise e
  File "/home/warmongr/projects/bms_charts/testing_module/can_module/can_conn_create.py", line 19, in connect_to_can
    power_up_can()
  File "/home/warmongr/projects/bms_charts/testing_module/can_module/can_powerup.py", line 29, in power_up_can
    raise CANPowerUpError
testing_module.can_module.can_exceptions.CANPowerUpError
2022-06-13 14:16:29,573 ERROR - LogGenerationFile: exception_logger_decorator - Line Number: 18 - Log:
Traceback (most recent call last):
  File "/home/warmongr/projects/controller_charts/testing_module/shared/exception_logger_decorator.py", line 15, in wrapper
    res = func(*args, **kwargs)
  File "/home/warmongr/projects/controller_charts/testing_module/can_module/get_can_conn.py", line 33, in get_can_connection
    raise e
  File "/home/warmongr/projects/controller_charts/testing_module/can_module/get_can_conn.py", line 26, in get_can_connection
    check_can_connection(can_bus)
  File "/home/warmongr/projects/controller_charts/testing_module/can_module/can_conn_check.py", line 28, in check_can_connection
    raise CANInternalConnectionError
testing_module.can_module.can_exceptions.CANInternalConnectionError
2022-06-13 14:19:56,614 ERROR - LogGenerationFile: can_write - Line Number: 25 - Log:'list' object has no attribute 'arbitration_id'
Traceback (most recent call last):
  File "/home/warmongr/projects/controller_charts/testing_module/can_module/can_write.py", line 22, in write_to_can
    can_bus.send(can_msg)
  File "/home/warmongr/projects/controller_charts/.testing_env/lib/python3.8/site-packages/can/interfaces/socketcan/socketcan.py", line 754, in send
    data = build_can_frame(msg)
  File "/home/warmongr/projects/controller_charts/.testing_env/lib/python3.8/site-packages/can/interfaces/socketcan/socketcan.py", line 177, in build_can_frame
    can_id = _compose_arbitration_id(msg)
  File "/home/warmongr/projects/controller_charts/.testing_env/lib/python3.8/site-packages/can/interfaces/socketcan/socketcan.py", line 297, in _compose_arbitration_id
    can_id = message.arbitration_id
AttributeError: 'list' object has no attribute 'arbitration_id'
2022-06-13 15:55:38,705 ERROR - LogGenerationFile: can_write - Line Number: 25 - Log:'list' object has no attribute 'arbitration_id'
Traceback (most recent call last):
  File "/home/warmongr/projects/controller_charts/testing_module/can_module/can_write.py", line 22, in write_to_can
    can_bus.send(can_msg)
  File "/home/warmongr/projects/controller_charts/.testing_env/lib/python3.8/site-packages/can/interfaces/socketcan/socketcan.py", line 754, in send
    data = build_can_frame(msg)
  File "/home/warmongr/projects/controller_charts/.testing_env/lib/python3.8/site-packages/can/interfaces/socketcan/socketcan.py", line 177, in build_can_frame
    can_id = _compose_arbitration_id(msg)
  File "/home/warmongr/projects/controller_charts/.testing_env/lib/python3.8/site-packages/can/interfaces/socketcan/socketcan.py", line 297, in _compose_arbitration_id
    can_id = message.arbitration_id
AttributeError: 'list' object has no attribute 'arbitration_id'
2022-06-13 16:05:54,639 ERROR - LogGenerationFile: can_write - Line Number: 25 - Log:Failed to transmit: Network is down [Error Code 100]
Traceback (most recent call last):
  File "/home/warmongr/projects/controller_charts/.testing_env/lib/python3.8/site-packages/can/interfaces/socketcan/socketcan.py", line 778, in _send_once
    sent = self.socket.send(data)
OSError: [Errno 100] Network is down

During handling of the above exception, another exception occurred:

Traceback (most recent call last):
  File "/home/warmongr/projects/controller_charts/testing_module/can_module/can_write.py", line 22, in write_to_can
    can_bus.send(can_msg)
  File "/home/warmongr/projects/controller_charts/.testing_env/lib/python3.8/site-packages/can/interfaces/socketcan/socketcan.py", line 763, in send
    sent = self._send_once(data, channel)
  File "/home/warmongr/projects/controller_charts/.testing_env/lib/python3.8/site-packages/can/interfaces/socketcan/socketcan.py", line 780, in _send_once
    raise can.CanOperationError(
can.exceptions.CanOperationError: Failed to transmit: Network is down [Error Code 100]
2022-06-13 16:07:09,318 ERROR - LogGenerationFile: can_write - Line Number: 25 - Log:Failed to transmit: Network is down [Error Code 100]
Traceback (most recent call last):
  File "/home/warmongr/projects/controller_charts/.testing_env/lib/python3.8/site-packages/can/interfaces/socketcan/socketcan.py", line 778, in _send_once
    sent = self.socket.send(data)
OSError: [Errno 100] Network is down

During handling of the above exception, another exception occurred:

Traceback (most recent call last):
  File "/home/warmongr/projects/controller_charts/testing_module/can_module/can_write.py", line 22, in write_to_can
    can_bus.send(can_msg)
  File "/home/warmongr/projects/controller_charts/.testing_env/lib/python3.8/site-packages/can/interfaces/socketcan/socketcan.py", line 763, in send
    sent = self._send_once(data, channel)
  File "/home/warmongr/projects/controller_charts/.testing_env/lib/python3.8/site-packages/can/interfaces/socketcan/socketcan.py", line 780, in _send_once
    raise can.CanOperationError(
can.exceptions.CanOperationError: Failed to transmit: Network is down [Error Code 100]
2022-06-13 16:10:20,972 ERROR - LogGenerationFile: can_write - Line Number: 25 - Log:Failed to transmit: Network is down [Error Code 100]
Traceback (most recent call last):
  File "/home/warmongr/projects/controller_charts/.testing_env/lib/python3.8/site-packages/can/interfaces/socketcan/socketcan.py", line 778, in _send_once
    sent = self.socket.send(data)
OSError: [Errno 100] Network is down

During handling of the above exception, another exception occurred:

Traceback (most recent call last):
  File "/home/warmongr/projects/controller_charts/testing_module/can_module/can_write.py", line 22, in write_to_can
    can_bus.send(can_msg)
  File "/home/warmongr/projects/controller_charts/.testing_env/lib/python3.8/site-packages/can/interfaces/socketcan/socketcan.py", line 763, in send
    sent = self._send_once(data, channel)
  File "/home/warmongr/projects/controller_charts/.testing_env/lib/python3.8/site-packages/can/interfaces/socketcan/socketcan.py", line 780, in _send_once
    raise can.CanOperationError(
can.exceptions.CanOperationError: Failed to transmit: Network is down [Error Code 100]
2022-06-13 16:10:24,378 ERROR - LogGenerationFile: can_write - Line Number: 25 - Log:Failed to transmit: Network is down [Error Code 100]
Traceback (most recent call last):
  File "/home/warmongr/projects/controller_charts/.testing_env/lib/python3.8/site-packages/can/interfaces/socketcan/socketcan.py", line 778, in _send_once
    sent = self.socket.send(data)
OSError: [Errno 100] Network is down

During handling of the above exception, another exception occurred:

Traceback (most recent call last):
  File "/home/warmongr/projects/controller_charts/testing_module/can_module/can_write.py", line 22, in write_to_can
    can_bus.send(can_msg)
  File "/home/warmongr/projects/controller_charts/.testing_env/lib/python3.8/site-packages/can/interfaces/socketcan/socketcan.py", line 763, in send
    sent = self._send_once(data, channel)
  File "/home/warmongr/projects/controller_charts/.testing_env/lib/python3.8/site-packages/can/interfaces/socketcan/socketcan.py", line 780, in _send_once
    raise can.CanOperationError(
can.exceptions.CanOperationError: Failed to transmit: Network is down [Error Code 100]
2022-06-13 16:44:58,153 ERROR - LogGenerationFile: exception_logger_decorator - Line Number: 18 - Log:
Traceback (most recent call last):
  File "/home/warmongr/projects/controller_charts/testing_module/can_module/can_conn_create.py", line 24, in connect_to_can
    can_bus = can.interface.Bus(
  File "/home/warmongr/projects/controller_charts/.testing_env/lib/python3.8/site-packages/can/interface.py", line 120, in __new__
    bus = cls(channel, *args, **kwargs)
  File "/home/warmongr/projects/controller_charts/.testing_env/lib/python3.8/site-packages/can/interfaces/socketcan/socketcan.py", line 691, in __init__
    bind_socket(self.socket, channel)
  File "/home/warmongr/projects/controller_charts/.testing_env/lib/python3.8/site-packages/can/interfaces/socketcan/socketcan.py", line 507, in bind_socket
    sock.bind((channel,))
OSError: [Errno 19] No such device

During handling of the above exception, another exception occurred:

Traceback (most recent call last):
  File "/home/warmongr/projects/controller_charts/testing_module/shared/exception_logger_decorator.py", line 15, in wrapper
    res = func(*args, **kwargs)
  File "/home/warmongr/projects/controller_charts/testing_module/can_module/get_can_conn.py", line 31, in get_can_connection
    raise e
  File "/home/warmongr/projects/controller_charts/testing_module/can_module/get_can_conn.py", line 25, in get_can_connection
    can_bus = connect_to_can()
  File "/home/warmongr/projects/controller_charts/testing_module/can_module/can_conn_create.py", line 29, in connect_to_can
    raise CANConnectionError
testing_module.can_module.can_exceptions.CANConnectionError
2022-06-13 16:45:47,182 ERROR - LogGenerationFile: exception_logger_decorator - Line Number: 18 - Log:
Traceback (most recent call last):
  File "/home/warmongr/projects/controller_charts/testing_module/can_module/can_conn_create.py", line 24, in connect_to_can
    can_bus = can.interface.Bus(
  File "/home/warmongr/projects/controller_charts/.testing_env/lib/python3.8/site-packages/can/interface.py", line 120, in __new__
    bus = cls(channel, *args, **kwargs)
  File "/home/warmongr/projects/controller_charts/.testing_env/lib/python3.8/site-packages/can/interfaces/socketcan/socketcan.py", line 691, in __init__
    bind_socket(self.socket, channel)
  File "/home/warmongr/projects/controller_charts/.testing_env/lib/python3.8/site-packages/can/interfaces/socketcan/socketcan.py", line 507, in bind_socket
    sock.bind((channel,))
OSError: [Errno 19] No such device

During handling of the above exception, another exception occurred:

Traceback (most recent call last):
  File "/home/warmongr/projects/controller_charts/testing_module/shared/exception_logger_decorator.py", line 15, in wrapper
    res = func(*args, **kwargs)
  File "/home/warmongr/projects/controller_charts/testing_module/can_module/get_can_conn.py", line 31, in get_can_connection
    raise e
  File "/home/warmongr/projects/controller_charts/testing_module/can_module/get_can_conn.py", line 25, in get_can_connection
    can_bus = connect_to_can()
  File "/home/warmongr/projects/controller_charts/testing_module/can_module/can_conn_create.py", line 29, in connect_to_can
    raise CANConnectionError
testing_module.can_module.can_exceptions.CANConnectionError
2022-06-13 16:54:15,667 ERROR - LogGenerationFile: exception_logger_decorator - Line Number: 18 - Log:
Traceback (most recent call last):
  File "/home/warmongr/projects/controller_charts/testing_module/can_module/can_conn_create.py", line 24, in connect_to_can
    can_bus = can.interface.Bus(
  File "/home/warmongr/projects/controller_charts/.testing_env/lib/python3.8/site-packages/can/interface.py", line 120, in __new__
    bus = cls(channel, *args, **kwargs)
  File "/home/warmongr/projects/controller_charts/.testing_env/lib/python3.8/site-packages/can/interfaces/socketcan/socketcan.py", line 691, in __init__
    bind_socket(self.socket, channel)
  File "/home/warmongr/projects/controller_charts/.testing_env/lib/python3.8/site-packages/can/interfaces/socketcan/socketcan.py", line 507, in bind_socket
    sock.bind((channel,))
OSError: [Errno 19] No such device

During handling of the above exception, another exception occurred:

Traceback (most recent call last):
  File "/home/warmongr/projects/controller_charts/testing_module/shared/exception_logger_decorator.py", line 15, in wrapper
    res = func(*args, **kwargs)
  File "/home/warmongr/projects/controller_charts/testing_module/can_module/get_can_conn.py", line 31, in get_can_connection
    raise e
  File "/home/warmongr/projects/controller_charts/testing_module/can_module/get_can_conn.py", line 25, in get_can_connection
    can_bus = connect_to_can()
  File "/home/warmongr/projects/controller_charts/testing_module/can_module/can_conn_create.py", line 29, in connect_to_can
    raise CANConnectionError
testing_module.can_module.can_exceptions.CANConnectionError
2022-06-13 17:30:25,881 ERROR - LogGenerationFile: exception_logger_decorator - Line Number: 18 - Log:
Traceback (most recent call last):
  File "/home/warmongr/projects/controller_charts/testing_module/shared/exception_logger_decorator.py", line 15, in wrapper
    res = func(*args, **kwargs)
  File "/home/warmongr/projects/controller_charts/testing_module/can_module/get_can_conn.py", line 33, in get_can_connection
    raise e
  File "/home/warmongr/projects/controller_charts/testing_module/can_module/get_can_conn.py", line 26, in get_can_connection
    check_can_connection(can_bus)
  File "/home/warmongr/projects/controller_charts/testing_module/can_module/can_conn_check.py", line 28, in check_can_connection
    raise CANInternalConnectionError
testing_module.can_module.can_exceptions.CANInternalConnectionError
2022-06-13 17:35:28,043 ERROR - LogGenerationFile: exception_logger_decorator - Line Number: 18 - Log:
Traceback (most recent call last):
  File "/home/warmongr/projects/controller_charts/testing_module/shared/exception_logger_decorator.py", line 15, in wrapper
    res = func(*args, **kwargs)
  File "/home/warmongr/projects/controller_charts/testing_module/can_module/get_can_conn.py", line 33, in get_can_connection
    raise e
  File "/home/warmongr/projects/controller_charts/testing_module/can_module/get_can_conn.py", line 26, in get_can_connection
    check_can_connection(can_bus)
  File "/home/warmongr/projects/controller_charts/testing_module/can_module/can_conn_check.py", line 28, in check_can_connection
    raise CANInternalConnectionError
testing_module.can_module.can_exceptions.CANInternalConnectionError
2022-06-13 18:10:20,313 ERROR - LogGenerationFile: exception_logger_decorator - Line Number: 18 - Log:
Traceback (most recent call last):
  File "/home/warmongr/projects/controller_charts/testing_module/shared/exception_logger_decorator.py", line 15, in wrapper
    res = func(*args, **kwargs)
  File "/home/warmongr/projects/controller_charts/testing_module/can_module/get_can_conn.py", line 33, in get_can_connection
    raise e
  File "/home/warmongr/projects/controller_charts/testing_module/can_module/get_can_conn.py", line 26, in get_can_connection
    check_can_connection(can_bus)
  File "/home/warmongr/projects/controller_charts/testing_module/can_module/can_conn_check.py", line 28, in check_can_connection
    raise CANInternalConnectionError
testing_module.can_module.can_exceptions.CANInternalConnectionError
